<?xml version="1.0" encoding="utf-8"?>
<!-- This URDF was automatically created by SolidWorks to URDF Exporter! Originally created by Stephen Brawner (brawner@gmail.com) 
     Commit Version: 1.5.1-0-g916b5db  Build Version: 1.5.7152.31018
     For more information, please see http://wiki.ros.org/sw_urdf_exporter -->
<robot
  name="arbot_v1">
  <link
    name="base_link">
    <inertial>
      <origin
        xyz="-4.0444E-17 3.1959E-17 0.019673"
        rpy="0 0 0" />
      <mass
        value="7.5962" />
      <inertia
        ixx="0.036506"
        ixy="6.3549E-19"
        ixz="-6.2655E-19"
        iyy="0.036506"
        iyz="-8.1867E-20"
        izz="0.070924" />
    </inertial>
    <visual>
      <origin
        xyz="0 0 0"
        rpy="0 0 0" />
      <geometry>
        <mesh
          filename="package://arbot_v1/meshes/base_link.STL" />
      </geometry>
      <material
        name="">
        <color
          rgba="0.65098 0.61961 0.58824 1" />
      </material>
    </visual>
    <collision>
      <origin
        xyz="0 0 0"
        rpy="0 0 0" />
      <geometry>
        <mesh
          filename="package://arbot_v1/meshes/base_link.STL" />
      </geometry>
    </collision>
  </link>
  <link
    name="L1">
    <inertial>
      <origin
        xyz="2.2081E-18 -0.016572 0.092612"
        rpy="0 0 0" />
      <mass
        value="2.087" />
      <inertia
        ixx="0.014661"
        ixy="2.8122E-20"
        ixz="-2.6202E-19"
        iyy="0.01493"
        iyz="0.0017382"
        izz="0.003955" />
    </inertial>
    <visual>
      <origin
        xyz="0 0 0"
        rpy="0 0 0" />
      <geometry>
        <mesh
          filename="package://arbot_v1/meshes/L1.STL" />
      </geometry>
      <material
        name="">
        <color
          rgba="1 1 1 1" />
      </material>
    </visual>
    <collision>
      <origin
        xyz="0 0 0"
        rpy="0 0 0" />
      <geometry>
        <mesh
          filename="package://arbot_v1/meshes/L1.STL" />
      </geometry>
    </collision>
  </link>
  <joint
    name="J1"
    type="revolute">
    <origin
      xyz="0 0 0"
      rpy="0 0 0" />
    <parent
      link="base_link" />
    <child
      link="L1" />
    <axis
      xyz="0 0 1" />
    <limit
      lower="-3.14"
      upper="3.14"
      effort="0"
      velocity="0" />
  </joint>
  <link
    name="L2">
    <inertial>
      <origin
        xyz="0.25 5.5511E-17 -0.030813"
        rpy="0 0 0" />
      <mass
        value="3.2114" />
      <inertia
        ixx="0.0031029"
        ixy="-1.5521E-17"
        ixz="-1.5552E-18"
        iyy="0.10413"
        iyz="-3.1137E-20"
        izz="0.10623" />
    </inertial>
    <visual>
      <origin
        xyz="0 0 0"
        rpy="0 0 0" />
      <geometry>
        <mesh
          filename="package://arbot_v1/meshes/L2.STL" />
      </geometry>
      <material
        name="">
        <color
          rgba="1 1 1 1" />
      </material>
    </visual>
    <collision>
      <origin
        xyz="0 0 0"
        rpy="0 0 0" />
      <geometry>
        <mesh
          filename="package://arbot_v1/meshes/L2.STL" />
      </geometry>
    </collision>
  </link>
  <joint
    name="J2"
    type="revolute">
    <origin
      xyz="0 0 0.2"
      rpy="1.5708 0 0" />
    <parent
      link="L1" />
    <child
      link="L2" />
    <axis
      xyz="0 0 1" />
    <limit
      lower="-3.14"
      upper="3.14"
      effort="0"
      velocity="0" />
  </joint>
  <link
    name="L3">
    <inertial>
      <origin
        xyz="0.2 2.7756E-17 0.030265"
        rpy="0 0 0" />
      <mass
        value="2.7228" />
      <inertia
        ixx="0.0026306"
        ixy="-7.6777E-18"
        ixz="2.9287E-18"
        iyy="0.061108"
        iyz="-1.2489E-19"
        izz="0.062846" />
    </inertial>
    <visual>
      <origin
        xyz="0 0 0"
        rpy="0 0 0" />
      <geometry>
        <mesh
          filename="package://arbot_v1/meshes/L3.STL" />
      </geometry>
      <material
        name="">
        <color
          rgba="1 1 1 1" />
      </material>
    </visual>
    <collision>
      <origin
        xyz="0 0 0"
        rpy="0 0 0" />
      <geometry>
        <mesh
          filename="package://arbot_v1/meshes/L3.STL" />
      </geometry>
    </collision>
  </link>
  <joint
    name="J3"
    type="revolute">
    <origin
      xyz="0.5 0 0"
      rpy="0 0 0" />
    <parent
      link="L2" />
    <child
      link="L3" />
    <axis
      xyz="0 0 1" />
    <limit
      lower="-3.14"
      upper="3.14"
      effort="0"
      velocity="0" />
  </joint>
  <link
    name="L4">
    <inertial>
      <origin
        xyz="0.088815 -1.2295E-07 -0.027191"
        rpy="0 0 0" />
      <mass
        value="1.5264" />
      <inertia
        ixx="0.0013542"
        ixy="1.9437E-08"
        ixz="-0.00033989"
        iyy="0.012224"
        iyz="6.9185E-10"
        izz="0.013013" />
    </inertial>
    <visual>
      <origin
        xyz="0 0 0"
        rpy="0 0 0" />
      <geometry>
        <mesh
          filename="package://arbot_v1/meshes/L4.STL" />
      </geometry>
      <material
        name="">
        <color
          rgba="1 1 1 1" />
      </material>
    </visual>
    <collision>
      <origin
        xyz="0 0 0"
        rpy="0 0 0" />
      <geometry>
        <mesh
          filename="package://arbot_v1/meshes/L4.STL" />
      </geometry>
    </collision>
  </link>
  <joint
    name="J4"
    type="revolute">
    <origin
      xyz="0.4 0 0"
      rpy="0 0 0" />
    <parent
      link="L3" />
    <child
      link="L4" />
    <axis
      xyz="0 0 1" />
    <limit
      lower="-3.14"
      upper="3.14"
      effort="0"
      velocity="0" />
  </joint>
</robot>