<?xml version="1.0" encoding="utf-8"?>
<!-- This URDF was automatically created by SolidWorks to URDF Exporter! Originally created by Stephen Brawner (brawner@gmail.com) 
     Commit Version: 1.5.1-0-g916b5db  Build Version: 1.5.7152.31018
     For more information, please see http://wiki.ros.org/sw_urdf_exporter -->
<robot
  name="ARbot_Rev2_1">
  <link
    name="base_link">
    <inertial>
      <origin
        xyz="-0.048162 2.704E-05 0.046465"
        rpy="0 0 0" />
      <mass
        value="2.8218" />
      <inertia
        ixx="0.0072703"
        ixy="3.7637E-06"
        ixz="-9.4116E-06"
        iyy="0.017945"
        iyz="-1.3551E-07"
        izz="0.02485" />
    </inertial>
    <visual>
      <origin
        xyz="0 0 0"
        rpy="0 0 0" />
      <geometry>
        <mesh
          filename="package://ARbot_Rev2_1/meshes/base_link.STL" />
      </geometry>
      <material
        name="">
        <color
          rgba="1 1 1 1" />
      </material>
    </visual>
    <collision>
      <origin
        xyz="0 0 0"
        rpy="0 0 0" />
      <geometry>
        <mesh
          filename="package://ARbot_Rev2_1/meshes/base_link.STL" />
      </geometry>
    </collision>
  </link>
  <link
    name="L1">
    <inertial>
      <origin
        xyz="-0.020939 0.032456 0.15718"
        rpy="0 0 0" />
      <mass
        value="4.8945" />
      <inertia
        ixx="0.0080325"
        ixy="-0.00011895"
        ixz="-0.00055075"
        iyy="0.010659"
        iyz="-0.00031043"
        izz="0.01049" />
    </inertial>
    <visual>
      <origin
        xyz="0 0 0"
        rpy="0 0 0" />
      <geometry>
        <mesh
          filename="package://ARbot_Rev2_1/meshes/L1.STL" />
      </geometry>
      <material
        name="">
        <color
          rgba="1 1 1 1" />
      </material>
    </visual>
    <collision>
      <origin
        xyz="0 0 0"
        rpy="0 0 0" />
      <geometry>
        <mesh
          filename="package://ARbot_Rev2_1/meshes/L1.STL" />
      </geometry>
    </collision>
  </link>
  <joint
    name="J1"
    type="revolute">
    <origin
      xyz="0 0 0"
      rpy="0 0 0" />
    <parent
      link="base_link" />
    <child
      link="L1" />
    <axis
      xyz="0 0 -1" />
    <limit
      lower="-3.14"
      upper="3.14"
      effort="0"
      velocity="0" />
  </joint>
  <link
    name="L2">
    <inertial>
      <origin
        xyz="0.13024 -8.302E-06 0.0047948"
        rpy="0 0 0" />
      <mass
        value="1.0764" />
      <inertia
        ixx="0.00061645"
        ixy="-6.3114E-09"
        ixz="3.6219E-05"
        iyy="0.0041444"
        iyz="-1.7237E-08"
        izz="0.0044137" />
    </inertial>
    <visual>
      <origin
        xyz="0 0 0"
        rpy="0 0 0" />
      <geometry>
        <mesh
          filename="package://ARbot_Rev2_1/meshes/L2.STL" />
      </geometry>
      <material
        name="">
        <color
          rgba="0.89804 0.91765 0.92941 1" />
      </material>
    </visual>
    <collision>
      <origin
        xyz="0 0 0"
        rpy="0 0 0" />
      <geometry>
        <mesh
          filename="package://ARbot_Rev2_1/meshes/L2.STL" />
      </geometry>
    </collision>
  </link>
  <joint
    name="J2"
    type="revolute">
    <origin
      xyz="0.059997 0.00059146 0.22402"
      rpy="1.5708 0 0" />
    <parent
      link="L1" />
    <child
      link="L2" />
    <axis
      xyz="0.0098577 0 0.99995" />
    <limit
      lower="-3.14"
      upper="3.14"
      effort="0"
      velocity="0" />
  </joint>
  <link
    name="L3">
    <inertial>
      <origin
        xyz="0.14863 0.00060846 -0.0010665"
        rpy="0 0 0" />
      <mass
        value="0.54852" />
      <inertia
        ixx="0.00012663"
        ixy="2.649E-06"
        ixz="-1.073E-06"
        iyy="0.0012574"
        iyz="-1.4025E-07"
        izz="0.0013366" />
    </inertial>
    <visual>
      <origin
        xyz="0 0 0"
        rpy="0 0 0" />
      <geometry>
        <mesh
          filename="package://ARbot_Rev2_1/meshes/L3.STL" />
      </geometry>
      <material
        name="">
        <color
          rgba="0.95686 0.95686 0.95686 1" />
      </material>
    </visual>
    <collision>
      <origin
        xyz="0 0 0"
        rpy="0 0 0" />
      <geometry>
        <mesh
          filename="package://ARbot_Rev2_1/meshes/L3.STL" />
      </geometry>
    </collision>
  </link>
  <joint
    name="J3"
    type="revolute">
    <origin
      xyz="0.31698 0 -0.0031249"
      rpy="0 0.0098578 0" />
    <parent
      link="L2" />
    <child
      link="L3" />
    <axis
      xyz="0 0 -1" />
    <limit
      lower="-3.14"
      upper="3.14"
      effort="0"
      velocity="0" />
  </joint>
  <link
    name="L4">
    <inertial>
      <origin
        xyz="0.040916 -4.5091E-05 -0.0014548"
        rpy="0 0 0" />
      <mass
        value="0.27788" />
      <inertia
        ixx="8.2697E-05"
        ixy="5.047E-07"
        ixz="9.599E-07"
        iyy="0.00012191"
        iyz="6.4804E-09"
        izz="0.00017868" />
    </inertial>
    <visual>
      <origin
        xyz="0 0 0"
        rpy="0 0 0" />
      <geometry>
        <mesh
          filename="package://ARbot_Rev2_1/meshes/L4.STL" />
      </geometry>
      <material
        name="">
        <color
          rgba="0.95686 0.95686 0.95686 1" />
      </material>
    </visual>
    <collision>
      <origin
        xyz="0 0 0"
        rpy="0 0 0" />
      <geometry>
        <mesh
          filename="package://ARbot_Rev2_1/meshes/L4.STL" />
      </geometry>
    </collision>
  </link>
  <joint
    name="J4"
    type="revolute">
    <origin
      xyz="0.343 -0.0002 0"
      rpy="0 -0.0098578 0" />
    <parent
      link="L3" />
    <child
      link="L4" />
    <axis
      xyz="-0.0098577 0 -0.99995" />
    <limit
      lower="-3.14"
      upper="3.14"
      effort="0"
      velocity="0" />
  </joint>
</robot>