<?xml version="1.0" encoding="utf-8"?>
<!-- This URDF was automatically created by SolidWorks to URDF Exporter! Originally created by Stephen Brawner (brawner@gmail.com) 
     Commit Version: 1.5.1-0-g916b5db  Build Version: 1.5.7152.31018
     For more information, please see http://wiki.ros.org/sw_urdf_exporter -->
<robot
  name="arbot_betav1">
  <link
    name="base_link">
    <inertial>
      <origin
        xyz="-3.697E-17 3.1321E-17 0.019673"
        rpy="0 0 0" />
      <mass
        value="7.5962" />
      <inertia
        ixx="0.036506"
        ixy="6.3549E-19"
        ixz="-6.2655E-19"
        iyy="0.036506"
        iyz="-8.1867E-20"
        izz="0.070924" />
    </inertial>
    <visual>
      <origin
        xyz="0 0 0"
        rpy="0 0 0" />
      <geometry>
        <mesh
          filename="package://arbot_betav1/meshes/base_link.STL" />
      </geometry>
      <material
        name="">
        <color
          rgba="0.65098 0.61961 0.58824 1" />
      </material>
    </visual>
    <collision>
      <origin
        xyz="0 0 0"
        rpy="0 0 0" />
      <geometry>
        <mesh
          filename="package://arbot_betav1/meshes/base_link.STL" />
      </geometry>
    </collision>
  </link>
  <link
    name="L1">
    <inertial>
      <origin
        xyz="0.0176 -5.4084E-18 0.10447"
        rpy="0 0 0" />
      <mass
        value="2.2189" />
      <inertia
        ixx="0.019403"
        ixy="8.4131E-20"
        ixz="-0.002034"
        iyy="0.019069"
        iyz="1.5898E-18"
        izz="0.0041182" />
    </inertial>
    <visual>
      <origin
        xyz="0 0 0"
        rpy="0 0 0" />
      <geometry>
        <mesh
          filename="package://arbot_betav1/meshes/L1.STL" />
      </geometry>
      <material
        name="">
        <color
          rgba="1 1 1 1" />
      </material>
    </visual>
    <collision>
      <origin
        xyz="0 0 0"
        rpy="0 0 0" />
      <geometry>
        <mesh
          filename="package://arbot_betav1/meshes/L1.STL" />
      </geometry>
    </collision>
  </link>
  <joint
    name="J1"
    type="revolute">
    <origin
      xyz="0 0 0"
      rpy="0 0 -1.5708" />
    <parent
      link="base_link" />
    <child
      link="L1" />
    <axis
      xyz="0 0 1" />
    <limit
      lower="-3.14"
      upper="3.14"
      effort="0"
      velocity="0" />
  </joint>
  <link
    name="L2">
    <inertial>
      <origin
        xyz="0.1585 2.7756E-17 -0.029635"
        rpy="0 0 0" />
      <mass
        value="2.3173" />
      <inertia
        ixx="0.0022368"
        ixy="-4.6951E-18"
        ixz="-8.4232E-19"
        iyy="0.035844"
        iyz="-6.7421E-20"
        izz="0.037278" />
    </inertial>
    <visual>
      <origin
        xyz="0 0 0"
        rpy="0 0 0" />
      <geometry>
        <mesh
          filename="package://arbot_betav1/meshes/L2.STL" />
      </geometry>
      <material
        name="">
        <color
          rgba="1 1 1 1" />
      </material>
    </visual>
    <collision>
      <origin
        xyz="0 0 0"
        rpy="0 0 0" />
      <geometry>
        <mesh
          filename="package://arbot_betav1/meshes/L2.STL" />
      </geometry>
    </collision>
  </link>
  <joint
    name="J2"
    type="revolute">
    <origin
      xyz="0 0 0.227"
      rpy="1.5708 0 1.5708" />
    <parent
      link="L1" />
    <child
      link="L2" />
    <axis
      xyz="0 0 1" />
    <limit
      lower="-3.14"
      upper="3.14"
      effort="0"
      velocity="0" />
  </joint>
  <link
    name="L3">
    <inertial>
      <origin
        xyz="0.1715 -2.7756E-17 0.029854"
        rpy="0 0 0" />
      <mass
        value="2.4443" />
      <inertia
        ixx="0.0023603"
        ixy="9.1581E-18"
        ixz="1.4294E-18"
        iyy="0.042834"
        iyz="8.4051E-20"
        izz="0.044363" />
    </inertial>
    <visual>
      <origin
        xyz="0 0 0"
        rpy="0 0 0" />
      <geometry>
        <mesh
          filename="package://arbot_betav1/meshes/L3.STL" />
      </geometry>
      <material
        name="">
        <color
          rgba="1 1 1 1" />
      </material>
    </visual>
    <collision>
      <origin
        xyz="0 0 0"
        rpy="0 0 0" />
      <geometry>
        <mesh
          filename="package://arbot_betav1/meshes/L3.STL" />
      </geometry>
    </collision>
  </link>
  <joint
    name="J3"
    type="revolute">
    <origin
      xyz="0.317 0 0"
      rpy="0 0 -0.014038" />
    <parent
      link="L2" />
    <child
      link="L3" />
    <axis
      xyz="0 0 1" />
    <limit
      lower="-3.14"
      upper="3.14"
      effort="0"
      velocity="0" />
  </joint>
  <link
    name="L4">
    <inertial>
      <origin
        xyz="0.032157 -0.00050545 -0.02597"
        rpy="0 0 0" />
      <mass
        value="0.95515" />
      <inertia
        ixx="0.00085086"
        ixy="4.9323E-09"
        ixz="-6.7978E-05"
        iyy="0.0024161"
        iyz="-5.4018E-10"
        izz="0.0028884" />
    </inertial>
    <visual>
      <origin
        xyz="0 0 0"
        rpy="0 0 0" />
      <geometry>
        <mesh
          filename="package://arbot_betav1/meshes/L4.STL" />
      </geometry>
      <material
        name="">
        <color
          rgba="1 1 1 1" />
      </material>
    </visual>
    <collision>
      <origin
        xyz="0 0 0"
        rpy="0 0 0" />
      <geometry>
        <mesh
          filename="package://arbot_betav1/meshes/L4.STL" />
      </geometry>
    </collision>
  </link>
  <joint
    name="J4"
    type="revolute">
    <origin
      xyz="0.343 0.00050536 0"
      rpy="0 0 0.014038" />
    <parent
      link="L3" />
    <child
      link="L4" />
    <axis
      xyz="0 0 1" />
    <limit
      lower="-3.14"
      upper="3.14"
      effort="0"
      velocity="0" />
  </joint>
</robot>