<?xml version="1.0" encoding="utf-8"?>
<!-- This URDF was automatically created by SolidWorks to URDF Exporter! Originally created by Stephen Brawner (brawner@gmail.com) 
     Commit Version: 1.5.1-0-g916b5db  Build Version: 1.5.7152.31018
     For more information, please see http://wiki.ros.org/sw_urdf_exporter -->
<robot
  name="ARbot_V1_4Export_5">
  <link
    name="base_link">
    <inertial>
      <origin
        xyz="-0.080223 5.3E-06 0.054528"
        rpy="0 0 0" />
      <mass
        value="4.9106" />
      <inertia
        ixx="0.011325"
        ixy="3.2424E-08"
        ixz="-1.8E-07"
        iyy="0.027106"
        iyz="-2.2091E-07"
        izz="0.036635" />
    </inertial>
    <visual>
      <origin
        xyz="0 0 0"
        rpy="0 0 0" />
      <geometry>
        <mesh
          filename="package://ARbot_V1_4Export_5/meshes/base_link.STL" />
      </geometry>
      <material
        name="">
        <color
          rgba="0.75294 0.75294 0.75294 1" />
      </material>
    </visual>
    <collision>
      <origin
        xyz="0 0 0"
        rpy="0 0 0" />
      <geometry>
        <mesh
          filename="package://ARbot_V1_4Export_5/meshes/base_link.STL" />
      </geometry>
    </collision>
  </link>
  <link
    name="L1">
    <inertial>
      <origin
        xyz="-1.302E-05 -0.0022648 0.17408"
        rpy="0 0 0" />
      <mass
        value="4.0253" />
      <inertia
        ixx="0.0065155"
        ixy="-5.2501E-07"
        ixz="3.4206E-07"
        iyy="0.007841"
        iyz="-0.00012217"
        izz="0.008449" />
    </inertial>
    <visual>
      <origin
        xyz="0 0 0"
        rpy="0 0 0" />
      <geometry>
        <mesh
          filename="package://ARbot_V1_4Export_5/meshes/L1.STL" />
      </geometry>
      <material
        name="">
        <color
          rgba="0.75294 0.75294 0.75294 1" />
      </material>
    </visual>
    <collision>
      <origin
        xyz="0 0 0"
        rpy="0 0 0" />
      <geometry>
        <mesh
          filename="package://ARbot_V1_4Export_5/meshes/L1.STL" />
      </geometry>
    </collision>
  </link>
  <joint
    name="J1"
    type="revolute">
    <origin
      xyz="0 0 0"
      rpy="0 0 0" />
    <parent
      link="base_link" />
    <child
      link="L1" />
    <axis
      xyz="0 0 -1" />
    <limit
      lower="-3.14"
      upper="3.14"
      effort="0"
      velocity="0" />
  </joint>
  <link
    name="L2">
    <inertial>
      <origin
        xyz="0.17319 -2.4719E-05 -0.00928"
        rpy="0 0 0" />
      <mass
        value="0.60289" />
      <inertia
        ixx="0.00023913"
        ixy="-2.2868E-19"
        ixz="1.3065E-05"
        iyy="0.0043525"
        iyz="5.6332E-20"
        izz="0.0043124" />
    </inertial>
    <visual>
      <origin
        xyz="0 0 0"
        rpy="0 0 0" />
      <geometry>
        <mesh
          filename="package://ARbot_V1_4Export_5/meshes/L2.STL" />
      </geometry>
      <material
        name="">
        <color
          rgba="0.79216 0.81961 0.93333 1" />
      </material>
    </visual>
    <collision>
      <origin
        xyz="0 0 0"
        rpy="0 0 0" />
      <geometry>
        <mesh
          filename="package://ARbot_V1_4Export_5/meshes/L2.STL" />
      </geometry>
    </collision>
  </link>
  <joint
    name="J2"
    type="revolute">
    <origin
      xyz="0 -0.10162 0.2271"
      rpy="1.5708 0 0" />
    <parent
      link="L1" />
    <child
      link="L2" />
    <axis
      xyz="0 0 1" />
    <limit
      lower="-3.14"
      upper="3.14"
      effort="0"
      velocity="0" />
  </joint>
  <link
    name="L3">
    <inertial>
      <origin
        xyz="0.053676 2.1181E-05 -0.046927"
        rpy="0 0 0" />
      <mass
        value="1.3426" />
      <inertia
        ixx="0.00046391"
        ixy="-7.926E-10"
        ixz="-4.1989E-07"
        iyy="0.0022357"
        iyz="1.4671E-07"
        izz="0.0023298" />
    </inertial>
    <visual>
      <origin
        xyz="0 0 0"
        rpy="0 0 0" />
      <geometry>
        <mesh
          filename="package://ARbot_V1_4Export_5/meshes/L3.STL" />
      </geometry>
      <material
        name="">
        <color
          rgba="0.95686 0.95686 0.95686 1" />
      </material>
    </visual>
    <collision>
      <origin
        xyz="0 0 0"
        rpy="0 0 0" />
      <geometry>
        <mesh
          filename="package://ARbot_V1_4Export_5/meshes/L3.STL" />
      </geometry>
    </collision>
  </link>
  <joint
    name="J3"
    type="revolute">
    <origin
      xyz="0.40104 -0.0001 0.0003"
      rpy="0 0 0" />
    <parent
      link="L2" />
    <child
      link="L3" />
    <axis
      xyz="0 0 -1" />
    <limit
      lower="-3.14"
      upper="3.14"
      effort="0"
      velocity="0" />
  </joint>
  <link
    name="L4">
    <inertial>
      <origin
        xyz="0.10356 0.0095095 -0.0011209"
        rpy="0 0 0" />
      <mass
        value="0.4635" />
      <inertia
        ixx="0.00016912"
        ixy="-2.8089E-08"
        ixz="6.4103E-08"
        iyy="0.00063381"
        iyz="1.0041E-08"
        izz="0.0007614" />
    </inertial>
    <visual>
      <origin
        xyz="0 0 0"
        rpy="0 0 0" />
      <geometry>
        <mesh
          filename="package://ARbot_V1_4Export_5/meshes/L4.STL" />
      </geometry>
      <material
        name="">
        <color
          rgba="0.95686 0.95686 0.95686 1" />
      </material>
    </visual>
    <collision>
      <origin
        xyz="0 0 0"
        rpy="0 0 0" />
      <geometry>
        <mesh
          filename="package://ARbot_V1_4Export_5/meshes/L4.STL" />
      </geometry>
    </collision>
  </link>
  <joint
    name="J4"
    type="revolute">
    <origin
      xyz="0.382 0 0"
      rpy="0 0 0" />
    <parent
      link="L3" />
    <child
      link="L4" />
    <axis
      xyz="0 0 -1" />
    <limit
      lower="-3.14"
      upper="3.14"
      effort="0"
      velocity="0" />
  </joint>
</robot>