<?xml version="1.0" encoding="utf-8"?>
<!-- This URDF was automatically created by SolidWorks to URDF Exporter! Originally created by Stephen Brawner (brawner@gmail.com) 
     Commit Version: 1.5.1-0-g916b5db  Build Version: 1.5.7152.31018
     For more information, please see http://wiki.ros.org/sw_urdf_exporter -->
<robot
  name="arbot_v1_Beta">
  <link
    name="base_link">
    <inertial>
      <origin
        xyz="-3.697E-17 3.2985E-17 0.019673"
        rpy="0 0 0" />
      <mass
        value="7.5962" />
      <inertia
        ixx="0.036506"
        ixy="6.3549E-19"
        ixz="-6.2655E-19"
        iyy="0.036506"
        iyz="-8.1867E-20"
        izz="0.070924" />
    </inertial>
    <visual>
      <origin
        xyz="0 0 0"
        rpy="0 0 0" />
      <geometry>
        <mesh
          filename="package://arbot_v1_Beta/meshes/base_link.STL" />
      </geometry>
      <material
        name="">
        <color
          rgba="0.65098 0.61961 0.58824 1" />
      </material>
    </visual>
    <collision>
      <origin
        xyz="0 0 0"
        rpy="0 0 0" />
      <geometry>
        <mesh
          filename="package://arbot_v1_Beta/meshes/base_link.STL" />
      </geometry>
    </collision>
  </link>
  <link
    name="L1">
    <inertial>
      <origin
        xyz="0.0176 -5.4084E-18 0.10447"
        rpy="0 0 0" />
      <mass
        value="2.2189" />
      <inertia
        ixx="0.019403"
        ixy="8.9009E-20"
        ixz="-0.002034"
        iyy="0.019069"
        iyz="1.5934E-18"
        izz="0.0041182" />
    </inertial>
    <visual>
      <origin
        xyz="0 0 0"
        rpy="0 0 0" />
      <geometry>
        <mesh
          filename="package://arbot_v1_Beta/meshes/L1.STL" />
      </geometry>
      <material
        name="">
        <color
          rgba="1 1 1 1" />
      </material>
    </visual>
    <collision>
      <origin
        xyz="0 0 0"
        rpy="0 0 0" />
      <geometry>
        <mesh
          filename="package://arbot_v1_Beta/meshes/L1.STL" />
      </geometry>
    </collision>
  </link>
  <joint
    name="J1"
    type="revolute">
    <origin
      xyz="0 0 0"
      rpy="0 0 -1.5708" />
    <parent
      link="base_link" />
    <child
      link="L1" />
    <axis
      xyz="0 0 1" />
    <limit
      lower="-3.14"
      upper="3.14"
      effort="0"
      velocity="0" />
  </joint>
  <link
    name="L2">
    <inertial>
      <origin
        xyz="0.1765 2.7756E-17 -0.029933"
        rpy="0 0 0" />
      <mass
        value="2.4932" />
      <inertia
        ixx="0.0024078"
        ixy="-6.7103E-18"
        ixz="-6.4685E-19"
        iyy="0.04574"
        iyz="-9.0768E-20"
        izz="0.047306" />
    </inertial>
    <visual>
      <origin
        xyz="0 0 0"
        rpy="0 0 0" />
      <geometry>
        <mesh
          filename="package://arbot_v1_Beta/meshes/L2.STL" />
      </geometry>
      <material
        name="">
        <color
          rgba="1 1 1 1" />
      </material>
    </visual>
    <collision>
      <origin
        xyz="0 0 0"
        rpy="0 0 0" />
      <geometry>
        <mesh
          filename="package://arbot_v1_Beta/meshes/L2.STL" />
      </geometry>
    </collision>
  </link>
  <joint
    name="J2"
    type="revolute">
    <origin
      xyz="0 0 0.227"
      rpy="1.5708 0 1.5708" />
    <parent
      link="L1" />
    <child
      link="L2" />
    <axis
      xyz="0 0 1" />
    <limit
      lower="-3.14"
      upper="3.14"
      effort="0"
      velocity="0" />
  </joint>
  <link
    name="L3">
    <inertial>
      <origin
        xyz="0.1535 -5.5511E-17 0.029543"
        rpy="0 0 0" />
      <mass
        value="2.2684" />
      <inertia
        ixx="0.0021892"
        ixy="7.3184E-18"
        ixz="1.0677E-18"
        iyy="0.033367"
        iyz="3.0423E-20"
        izz="0.034764" />
    </inertial>
    <visual>
      <origin
        xyz="0 0 0"
        rpy="0 0 0" />
      <geometry>
        <mesh
          filename="package://arbot_v1_Beta/meshes/L3.STL" />
      </geometry>
      <material
        name="">
        <color
          rgba="1 1 1 1" />
      </material>
    </visual>
    <collision>
      <origin
        xyz="0 0 0"
        rpy="0 0 0" />
      <geometry>
        <mesh
          filename="package://arbot_v1_Beta/meshes/L3.STL" />
      </geometry>
    </collision>
  </link>
  <joint
    name="J3"
    type="revolute">
    <origin
      xyz="0.353 0 0"
      rpy="0 0 -0.014038" />
    <parent
      link="L2" />
    <child
      link="L3" />
    <axis
      xyz="0 0 1" />
    <limit
      lower="-3.14"
      upper="3.14"
      effort="0"
      velocity="0" />
  </joint>
  <link
    name="L4">
    <inertial>
      <origin
        xyz="0.056927 -6.0542E-08 -0.026659"
        rpy="0 0 0" />
      <mass
        value="1.2102" />
      <inertia
        ixx="0.0010761"
        ixy="6.5693E-09"
        ixz="-0.00015378"
        iyy="0.0055353"
        iyz="-1.2235E-12"
        izz="0.0061488" />
    </inertial>
    <visual>
      <origin
        xyz="0 0 0"
        rpy="0 0 0" />
      <geometry>
        <mesh
          filename="package://arbot_v1_Beta/meshes/L4.STL" />
      </geometry>
      <material
        name="">
        <color
          rgba="1 1 1 1" />
      </material>
    </visual>
    <collision>
      <origin
        xyz="0 0 0"
        rpy="0 0 0" />
      <geometry>
        <mesh
          filename="package://arbot_v1_Beta/meshes/L4.STL" />
      </geometry>
    </collision>
  </link>
  <joint
    name="J4"
    type="revolute">
    <origin
      xyz="0.307 0 0"
      rpy="0 0 0.014038" />
    <parent
      link="L3" />
    <child
      link="L4" />
    <axis
      xyz="0 0 1" />
    <limit
      lower="-3.14"
      upper="3.14"
      effort="0"
      velocity="0" />
  </joint>
</robot>